Traceback (most recent call last):
  File "/home/wifi/Downloads/simple/Idea-validation-ip-ccn/simpleSock.py", line 40, in <module>
    _cache['drp'] = int(sys.argv[4])
IndexError: list index out of range

During handling of the above exception, another exception occurred:

Traceback (most recent call last):
  File "/home/wifi/Downloads/simple/Idea-validation-ip-ccn/simpleSock.py", line 46, in <module>
    raise Exception("No value for number of nodes")
Exception: No value for number of nodes
